<mujoco>
	<compiler angle="radian"
			inertiafromgeom="auto"
			texturedir="textures/"
			meshdir="mesh/visual/"/>
	<option timestep="1e-4"
			iterations="35"
			tolerance="1e-10"
			impratio="20"
			cone="elliptic" />
	<size njmax="10000" nconmax="5000" nstack="15000000"/>

	<default>
		<geom contype='1' conaffinity='1' condim='6' solref="2e-4 1" solimp=".995 .995 .01" friction="1.3 0.01 0.0005" />
		<joint armature="0.01" damping=".1"/>
		<!-- <site rgba='1 1 1 0' /> -->
		<default class="gripperTrans">
			<joint damping='30' />
		</default>
		<default class="gripperRot">
			<joint damping='65'/>
		</default>
		<default class="GRIPPER">
			<joint damping='15'/>
		</default>
	</default>

	<visual>
		<map fogstart="3" fogend="5" znear="0.05"/>
		<quality shadowsize="2048"/>
		<scale  framelength="2.5"
		framewidth="0.06"
		contactwidth="1.1"
		contactheight="0.01"
		forcewidth="0.01"
		/>
	</visual>

	<!--Assets-->
	<asset>
		<!--Textures-->
		<texture name="ur5_tex"     type="2d"       builtin="flat" height="32" width="32" rgb1="0.45 0.45 0.45" />
		<texture name="gripper_tex" type="2d"       builtin="flat" height="32" width="32" rgb1="0.45 0.45 0.45" rgb2="0 0 0"/>
		<texture name="bench_tex"   type="2d"       builtin="flat" height="32" width="32" rgb1="0.7 0.7 0.7" />
		<texture name="sky_tex"     type="skybox"   builtin="gradient" width="100" height="100" rgb1="1 1 1" rgb2="0.3 0.3 0.8" />
		<texture name="texgeom"     type="cube"     builtin="flat" mark="cross" width="127" height="1278" rgb1="0.8 0.6 0.4" rgb2="0.8 0.6 0.4" markrgb="1 1 1" random="0.01" />
		<texture name="floor_tex"   type="2d"        builtin="checker" rgb1=".2 .3 .4" rgb2=".1 .2 .3" width="100" height="100" />
		<texture name="wood"        type="cube"     file="wood2.png"/>
		<texture name="metal"        type="cube"     file="metal2.png"/>
		<!--Materials-->
		<material name="ur5_mat"        texture="ur5_tex"   shininess="0.9" specular="0.75" reflectance="0.3"/>
		<material name="gripper_mat"    texture="gripper_tex"   shininess="0.9" specular="0.75" reflectance="0.4"/>
		<material name='floor_mat'      texture="floor_tex"  shininess="0.8" texrepeat="10 10" specular="0.7"  reflectance="0.5" />
		<material name='geom'           texture="texgeom"   texuniform="true" />
		<material name="bench_mat"      texture="metal"   shininess="0.1" specular="0.5" reflectance="0.2"/>
		<material name="tablecube"      texture="wood" rgba=".8 .8 .8 1"/>
	</asset>

	<worldbody>
		<!--Lighting parameters-->
		<light name="light3" mode="targetbody" target="gripperLink_0" directional="true" pos="1 1 5" />

		<geom type='capsule' size='0.03 0.3' pos='-1.7 -2 0' rgba='1 0 0 1' quat='0.7071068  0 0.7071068 0' />
		<geom type='capsule' size='0.03 0.3' pos='-2 -1.7 0' rgba='0 1 0 1' quat='0.7071068  0.7071068 0 0' />
		<geom type='capsule' size='0.03 0.3' pos='-2 -2 0.3' rgba='0 0 1 1' />

		<!--Floor Property-->
		<geom name='floor' pos='0 0 -1.5' size='5 5 0.1'  type='plane' rgba='0.1 0.2 0.3 1' />

		<body name='camera' pos='2.4 0 2' euler="0 0.6 0" >
		<geom pos='0 0 0' type='box' size='0.01 0.1 0.01' density='10'  />
		<camera name='c1' fovy="55" pos="0 .01 .01">
		</camera>
		</body> 

		<!-- Insert table here! -->

		<!-- GRIPPER -->
		<!-- <geom name='eePoint' pos='0 0.3 0' type='box' size='0.005 0.005 0.005' rgba='1 0 0 1' /> -->
		<body name="gripperLink_0" pos="0 0 2.5" >
			<joint name="trans_x" type="slide" class="gripperTrans" pos="0 0 0" axis="1 0 0" />
			<joint name="trans_y" type="slide" class="gripperTrans" pos="0 0 0" axis="0 1 0" />
			<joint name="trans_z" type="slide" class="gripperTrans" pos="0 0 0" axis="0 0 1" />
			<joint name="rot_x" class="gripperRot" pos="0 0 0" axis="1 0 0" />
			<joint name="rot_y" class="gripperRot" pos="0 0 0" axis="0 1 0" />
			<joint name="rot_z" class="gripperRot" pos="0 0 0" axis="0 0 1" />

			<geom pos='0 -0.23 0' type='cylinder' size='0.12 0.08' quat='0.7071068 0.7071068 0 0' condim='3' density='10' />
			<geom pos='0.12 -0.23 0' type='sphere' size='0.01' rgba='1 0 0 1' density='1' />
			<geom pos='0 -0.22 0.12' type='sphere' size='0.01' rgba='0 0 1 1' density='1' />

			<!-- <geom pos='0 -0.19 0.05' type='box' size='0.01 0.01 0.05' condim='3'  density='10'  />
			-->

			<body name='left_finger' pos='-0.06 -0.14 0' quat='1 0 0 0'>
				<joint name='l_f' type='slide' pos='0 0 0' axis='1 0 0' range='0 0.05' damping='10' limited='true' solreflimit='1e-3 1' solimplimit=".99 .99 .01" />
				<geom pos='0 0.05 0' type='box' size='0.007 0.05 0.015' condim='6' friction='1 0.02 0.0005' density='10'  />
				<!-- Fingertip -->
				<body name='left_fingertip' pos='0 0.14 0' quat='0.7071068 0 0.7071068 0'>
					<geom pos='0 0 0' type='box' size='0.04 0.04 0.01' condim='6'  friction='1 0.04 0.001' solref='1e-4 1' density='2000'  />
					<!-- Four anchor points for cross tendons, in order to implement shear force sensor -->
					<site name="left_cross_bottom_1" pos="0.04  0 0.01" type='sphere' size='0.003' />
					<site name="left_cross_bottom_2" pos="-0.04 0 0.01" type='sphere' size='0.003' />
					<site name="left_cross_bottom_3" pos="0  0.04 0.01" type='sphere' size='0.003' />
					<site name="left_cross_bottom_4" pos="0 -0.04 0.01" type='sphere' size='0.003' />
					<body name='left_finger_skin' pos='0 0 0.015' >
						<geom pos='0 0 0' name='left_tip' type='box' size='0.06 0.06 0.003'  solref='1e-4 1'  />
						<site pos='0 0 -0.003' type='box' size='0.061 0.061 0.006' name='leftFingerMainTouch' rgba='1 1 0 0.2' />
					</body>
				</body>
			</body>

			<body name='right_finger' pos='0.06 -0.14 0' quat='1 0 0 0'>
				<joint name='r_f' type='slide' pos='0 0 0' axis='-1 0 0' range='0 0.05' damping='10' limited='true'  solreflimit='1e-3 1' solimplimit=".99 .99 .01" />
				<geom pos='0 0.05 0' type='box' size='0.007 0.05 0.015' condim='6' friction='1 0.02 0.0005' density='10'  />
				<!-- Fingertip -->
				<body name='right_fingertip' pos='0 0.14 0' quat='-0.7071068 0 0.7071068 0'>
					<geom pos='0 0 0' type='box' size='0.04 0.04 0.01' condim='6'  friction='1 0.04 0.001' solref='1e-4 1' density='2000'  />
					<!-- Four anchor points for cross tendons, in order to implement shear force sensor -->
					<site name="right_cross_bottom_1" pos="0.04  0 0.01" type='sphere' size='0.003' />
					<site name="right_cross_bottom_2" pos="-0.04 0 0.01" type='sphere' size='0.003' />
					<site name="right_cross_bottom_3" pos="0  0.04 0.01" type='sphere' size='0.003' />
					<site name="right_cross_bottom_4" pos="0 -0.04 0.01" type='sphere' size='0.003' />
					<body name='right_finger_skin' pos='0 0 0.015' >
						<geom pos='0 0 0' name='right_tip' type='box' size='0.06 0.06 0.003'  solref='1e-4 1' />
						<site pos='0 0 -0.003' type='box' size='0.061 0.061 0.006' name='rightFingerMainTouch' rgba='1 1 0 0.2' />
					</body>
				</body>
			</body>
		</body>

	<!-- Insert velcro here! -->



	</worldbody>

	<tendon> 

	<!-- Insert tendons here! -->
	</tendon>
	<!-- No damping term for velcro tendons -->

	<actuator>
		<!--UR5-->
		<position name='trans_x_p' joint='trans_x' kp="1300" forcerange="-400 400"/>
		<position name='trans_y_p' joint='trans_y' kp="1300" forcerange="-400 400"/>
		<position name='trans_z_p' joint='trans_z' kp="1300" forcerange="-400 400"/>
		<position name='rot_x_p' ctrllimited="true" ctrlrange="-3.14159 3.14159" joint='rot_x' forcerange="-350 350" kp="10" />
		<position name='rot_y_p' ctrllimited="true" ctrlrange="-3.14159 3.14159" joint='rot_y' forcerange="-350 350" kp="10" />
		<position name='rot_z_p' ctrllimited="true" ctrlrange="-3.14159 3.14159" joint='rot_z' forcerange="-350 350" kp="10" />
		<velocity name='trans_x_v' joint='trans_x' forcerange="-350 350" kv="130" />
		<velocity name='trans_y_v' joint='trans_y' forcerange="-350 350" kv="130" />
		<velocity name='trans_z_v' joint='trans_z' forcerange="-350 350" kv="130" />
		<velocity name='rot_x_v' joint='rot_x' forcerange="-350 350" kv="10" />
		<velocity name='rot_y_v' joint='rot_y' forcerange="-350 350" kv="10" />
		<velocity name='rot_z_v' joint='rot_z' forcerange="-350 350" kv="10" />

		<!--Gripper-->
		<position name='finger_p' joint="l_f" />
		<velocity name='finger_v' class="GRIPPER" joint='l_f' />
	</actuator>

	<equality>
		<joint name='fingers' joint1="r_f" joint2="l_f" polycoef='0 1 0 0 0' solref="3e-4 1" solimp=".99 .99 .01" />
	</equality>

	<contact>
		
		<!-- Insert contact here! -->
	</contact>

	<sensor>
		<force name='lf_main' site='leftFingerMainTouch' cutoff='800' />
		<force name='rf_main' site='rightFingerMainTouch' cutoff="800" />
		<torque name='lf_main_torque' site='leftFingerMainTouch' cutoff='800' />
		<torque name='rf_main_torque' site='rightFingerMainTouch' cutoff="800" />
		<!-- Always put these two tri-axis force sensor in the first, 
		when adding new sensor keep in mind that force sensordata has three elements -->
	</sensor>

</mujoco>